Workbook
Name Apps_Stategy: #REF!
Name AREA_TO_PASTE1: 'RFQ Data'!$A$1
Name AREA_TO_PASTE2: PRICE!$A$1
Name AREA_TO_PASTE3: 'PROCESS & CAPEX'!$A$1
Name COEFF_1: PRICE!$T$63
Name COEFF_2: PRICE!$T$64
Name COEFF_3: PRICE!$T$65
Name Cur_rate: 'Small runner-PRICE'!$C$6
Name CUR_RM_Index: '[1]RFQ Data'!$K$24
Name Data5_Agressivity: PRICE!$O$58
Name INDEX_IMPACT: 'PROCESS & CAPEX'!$M$13:$M$26
Name PRICE_inCUR: PRICE!$N$51
Name QuotingCUR: 'RFQ Data'!$H$20
Name SIMUL_INDEXATION: 'PROCESS & CAPEX'!$L$13:$L$26
Name SIMUL_NEWRATE: PRICE!$AU$7
Name SIMUL_PRICE: PRICE!$W$7
Name SIMUL_VOL: PRICE!$Y$41
Name SIMUL_VOL_PRODUCTIVITY: PRICE!$AO$2:$AS$3
Name Small_Runner_Zone: 'Small runner-PRICE'!$D$32,'Small runner-PRICE'!$D$10:$D$15
Name Strategy_type: #REF!
Name Target_price: 'RFQ Data'!$C$11
Name Trader: #REF!
Name User1: #REF!
Name user3: #REF!
Name User4: #REF!

Sheet RFQ Data
B1: Requester | C1: Mark Z. | F1: RFQ DATA - Costing process | J1: RFQ# | L1: 25626-BRU-00
C2: Sales has provided the following information | I2: Costing leader | L2: FRANCIS
B3: Project | C3: Riyong/RY5.578.100A | I3: Type of product line | L3: Brushes
B4: Customer Name | C4: Riyong | I4: Application | L4: HVAC blowers
B5: Customer location | C5: China | I5: Stategic segment ? | J5: YES | L5: Comfort & Auxiliary motors
I6: Type of process | L6: B-Alt & Auxilairy / t or a
B7: Customer area | C7: China + South pacific | E7: Zone | F7: 1
B8: Target price | C8: 0 | D8: RMB | E8: in Currency of customer Area
B9: Target price | C9: 0 | D9: RMB | E9: In Currency of AVO manufacturing plant | J9: Package volume
B10: exchange rate : | C10: 1 | D10: RMBRMB | E10: We are selling in the expected currency, this is a good news | J10: 500 | K10: Kparts
D11: SOP
B12: Years | C12: 2025 | D12: 2026 | E12: 2027 | F12: 2028 | G12: 2029 | H12: 2030 | J12: Business link
B13: Qty (Kp) | C13: 0 | D13: 500 | E13: 500 | F13: 500 | G13: 500 | H13: 500 | J13: 0 | K13: of average yearly sales
B14: Productivity plan | C14: 0 | D14: 0 | E14: 0 | F14: 0 | G14: 0 | H14: 0 | I14: or | J14: 0 | K14: kRMB
B15: Target price | C15: 0 | D15: 0 | E15: 0 | F15: 0 | G15: 0 | H15: 0 | J15: to pay at tooling order
B16: Capacity to set up | C16: 0 | D16: 600 | E16: 600 | F16: 600 | G16: 600 | H16: 600
A17: Definition of the manufacturing location
A18: For | C18: China + South pacific | D18: the strategy for | G18: B-Alt & Auxilairy / t or a | H18: is to finish the product in | J18: Tianjin | K18: in zone | L18: 1
A19: Because the delivery takes place in | E19: same | F19: zone, recommandation is | H19: DDP | I19: China
A20: For this plant our normal terms of payment are | E20: 60 | F20: days the plant invoices in | H20: RMB | I20: 0 | J20: payment term negociated (days)
A21: As delivery conditions quoted | C21: EXW | F21: we consider a customer pick up every | G21: 2 | H21: EUR | I21: RMB | J21: USD | K21: INR | L21: KWON
A22: we will keep a safety stock of | D22: 7 | E22: days of averge customer forecast | H22: 0.125 | I22: 1 | J22: 0.1375 | K22: 11.875 | L22: 0.195
A23: We consider that the leadtime within a the same zone is | F23: 1 | H23: second currency : | J23: EURRMB | K23: 8
G24: INDEXATION : Product includes… | J24: EURRMB | K24: 8
A25: These parameters lead to the following levels of inventory | G25: Copper | H25: 8.65 | I25: EUR | J25: /kg | K25: Material cost only (LME)
B26: Semi-finished product in transit /AVOplants | E26: 6.4603843 | F26: w days* | G26: Silver | H26: 1137 | I26: EUR | J26: /kg | K26: Material cost only (LME)
B27: Finished product safety stock in house | E27: 7 | G27: Nat Graphite | H27: 2.7764034 | I27: EUR | J27: /kg
B28: AvG Finsished product in house to cover pick up | E28: 9.3333333 | G28: Art Graphite | H28: 7.5 | I28: EUR | J28: /kg
B29: Finished product in transit to the customer | E29: 0 | G29: Mix with Nat | H29: 3.1937069 | I29: EUR | J29: /kg | K29: RM cost of black-mix /nat. graph.
B30: Finished product at customer | E30: 0 | G30: Mix with Art | H30: 7.256 | I30: EUR | J30: /kg | K30: RM cost of black-mix /art. graph.
B31: Total finished product inventory | E31: 22.793718 | F31: days | H31: 0 | I31: EUR | J31: /kg
B32: w days* = weighted days = days x %price | G32: Other mix | H32: 22 | I32: EUR | J32: /kg | K32: Price is adjusted /quoted grade
B33: The WIP in the plant considers | E33: 7 | F33: days of RM | G33: Plate | H33: 90 | I33: EUR | J33: /kg | K33: Price is adjusted /quoted grade
H34: 0 | I34: EUR | J34: /kg
O64: =IF(G64<>0,H64/G64*(1-'RFQ Data'!$I$36),0) -> 0
O65: =IF(G65<>0,H65/G65*(1-'RFQ Data'!$I$36),0) -> 0
O66: =IF(G66<>0,H66/G66*(1-'RFQ Data'!$I$36),0) -> 0
O67: =IF(G67<>0,H67/G67*(1-'RFQ Data'!$I$36),0) -> 0
O68: =IF(G68<>0,H68/G68*(1-'RFQ Data'!$I$36),0) -> 0
O69: =IF(G69<>0,H69/G69*(1-'RFQ Data'!$I$36),0) -> 0
...

Sheet PRICE
A1: Profitability from COSTING | B1: 2025 | C1: 2026 | D1: 2027 | E1: 2028 | F1: 2029 | G1: 2030 | H1: 2031 | K1: TRI / ROI result | L1: 0.30009445 | M1: 0.3 | N1: ROI target | Q1: Riyong/RY5.578.100A Riyong China | S1: I | T1: Limit of frozen data | V1: SIMULATION ZONE | AA1: =Q1 -> Riyong/RY5.578.100A Riyong China | AC1: Profitability (SIMULATION) | AD1: 2023 | AE1: 2024 | AF1: 2025 | AG1: 2026 | AH1: 2027 | AI1: 2028 | AJ1: 2029 | AM1: I | AN1: NEW | AO1: =AE1 -> 2024 | AP1: =AF1 -> 2025 | AQ1: =AG1 -> 2026 | AR1: =AH1 -> 2027 | AS1: =AI1 -> 2028 | AU1: Average | AW1: I | AX1: Profitability (SIMULATION) | AY1: 2023 | AZ1: 2024 | BA1: 2025 | BB1: 2026 | BC1: 2027 | BD1: 2028 | BE1: 2029
A2: Qtes | B2: 0 | C2: 500 | D2: 500 | E2: 500 | F2: 500 | G2: 500 | H2: 0 | I2: 500 | K2: Cash Generation | L2: 0 | O2: RFQ# | Q2: 25626-BRU-00 | S2: I | Y2: RFQ# | AA2: =Q2 -> 25626-BRU-00 | AC2: Qtes | AD2: 0 | AE2: =IF(AO2="",C2,AO2) -> 500 | AF2: =IF(AP2="",D2,AP2) -> 500 | AG2: =IF(AQ2="",E2,AQ2) -> 500 | AH2: =IF(AR2="",F2,AR2) -> 500 | AI2: =IF(AS2="",G2,AS2) -> 500 | AJ2: 0 | AM2: I | AN2: volume | AT2: Kparts | AU2: =AVERAGE(AE2:AI2) -> 500 | AW2: I | AX2: Qtes | AY2: =AD2 -> 0 | AZ2: =AE2 -> 500 | BA2: =AF2 -> 500 | BB2: =AG2 -> 500 | BC2: =AH2 -> 500 | BD2: =AI2 -> 500 | BE2: =AJ2 -> 0
A3: Productivity | B3: 0 | C3: 0 | D3: 0 | E3: 0 | F3: 0 | G3: 0 | H3: 0 | K3: VAN | L3: 0.018335211 | N3: ROI target changed | Q3: #VALUE! | S3: I | T3: ADJUST THE PRICE TO FINAL PRICE TARGETTED | AC3: Productivity | AD3: =B3 -> 0 | AE3: =IF(AO3="",C3,AO3) -> 0 | AF3: =IF(AP3="",D3,AP3) -> 0 | AG3: =IF(AQ3="",E3,AQ3) -> 0 | AH3: =IF(AR3="",F3,AR3) -> 0 | AI3: =IF(AS3="",G3,AS3) -> 0 | AJ3: =H3 -> 0 | AM3: I | AN3: productivity | AT3: % | AW3: I | AX3: Productivity | AY3: =AD3 -> 0 | AZ3: =AE3 -> 0 | BA3: =AF3 -> 0 | BB3: =AG3 -> 0 | BC3: =AH3 -> 0 | BD3: =AI3 -> 0 | BE3: =AJ3 -> 0
A4: Part impacted by productivity | B4: 0.91768565 | C4: 0.91768565 | D4: 0.91768565 | E4: 0.91768565 | F4: 0.91768565 | G4: 0.91768565 | H4: 0.91768565 | Q4: Calculation OK | S4: I | T4: Initial Target price (RFQ data) | W4: ='RFQ Data'!C9 -> 0 | X4: ='RFQ Data'!D9 -> RMB | Y4: Avo plant currency | AC4: Part impacted by productivity | AD4: =AD7-AD6-AD5 -> -0.41544772 | AE4: =AD4*(1-AE3) -> -0.41544772 | AF4: =AE4*(1-AF3) -> -0.41544772 | AG4: =AF4*(1-AG3) -> -0.41544772 | AH4: =AG4*(1-AH3) -> -0.41544772 | AI4: =AH4*(1-AI3) -> -0.41544772 | AJ4: =AI4*(1-AJ3) -> -0.41544772 | AM4: I | AN4: WARNING : VOLUME CHANGE HERE MUST NOT IMPACT THE PACKAGE VOLUME OFFER | AW4: I | AX4: Part impacted by productivity | AY4: =AD4/$AV$7 -> -0.051930965 | AZ4: =AE4/$AV$7 -> -0.051930965 | BA4: =AF4/$AV$7 -> -0.051930965 | BB4: =AG4/$AV$7 -> -0.051930965 | BC4: =AH4/$AV$7 -> -0.051930965 | BD4: =AI4/$AV$7 -> -0.051930965 | BE4: =AJ4/$AV$7 -> -0.051930965
A5: Packaging and transportation | B5: 0.10202582 | C5: 0.10202582 | D5: 0.10202582 | E5: 0.10202582 | F5: 0.10202582 | G5: 0.10202582 | H5: 0.10202582 | S5: I | W5: ='RFQ Data'!C8 -> 0 | X5: ='RFQ Data'!D8 -> RMB | Y5: Customer curenccy | AC5: Packaging and transportation | AD5: =B5 -> 0.10202582 | AE5: =C5 -> 0.10202582 | AF5: =D5 -> 0.10202582 | AG5: =E5 -> 0.10202582 | AH5: =F5 -> 0.10202582 | AI5: =G5 -> 0.10202582 | AJ5: =H5 -> 0.10202582 | AM5: I | AW5: I | AX5: Packaging and transportation | AY5: =AD5/$AV$7 -> 0.012753228 | AZ5: =AE5/$AV$7 -> 0.012753228 | BA5: =AF5/$AV$7 -> 0.012753228 | BB5: =AG5/$AV$7 -> 0.012753228 | BC5: =AH5/$AV$7 -> 0.012753228 | BD5: =AI5/$AV$7 -> 0.012753228 | BE5: =AJ5/$AV$7 -> 0.012753228
A6: Indexed material | B6: 0.31342189 | C6: 0.31342189 | D6: 0.31342189 | E6: 0.31342189 | F6: 0.31342189 | G6: 0.31342189 | H6: 0.31342189 | J6: 2025 | K6: 2026 | L6: 2027 | M6: 2028 | N6: 2029 | O6: 2030 | P6: Max productivity | S6: I | AC6: Indexed material | AD6: =B6 -> 0.31342189 | AE6: =C6 -> 0.31342189 | AF6: =D6 -> 0.31342189 | AG6: =E6 -> 0.31342189 | AH6: =F6 -> 0.31342189 | AI6: =G6 -> 0.31342189 | AJ6: =H6 -> 0.31342189 | AM6: I | AN6: Currency rate of costing | AU6: new currency rate | AW6: I | AX6: Indexed material | AY6: =AD6/$AV$7 -> 0.039177736 | AZ6: =AE6/$AV$7 -> 0.039177736 | BA6: =AF6/$AV$7 -> 0.039177736 | BB6: =AG6/$AV$7 -> 0.039177736 | BC6: =AH6/$AV$7 -> 0.039177736 | BD6: =AI6/$AV$7 -> 0.039177736 | BE6: =AJ6/$AV$7 -> 0.039177736
A7: Final price | B7: 1.3331334 | C7: 1.3331334 | D7: 1.3331334 | E7: 1.3331334 | F7: 1.3331334 | G7: 1.3331334 | H7: 1.3331334 | I7: RMB | J7: 0 | K7: 0 | L7: 0 | M7: 0 | N7: 0 | O7: 0 | S7: I | U7: New PRICE for simulation | X7: =X4 -> RMB | AA7: -----> | AC7: Final price (Sales target) | AD7: =T12 -> 0 | AE7: =+AE4+AE5+AE6 -> 0 | AF7: =+AF4+AF5+AF6 -> 0 | AG7: =+AG4+AG5+AG6 -> 0 | AH7: =+AH4+AH5+AH6 -> 0 | AI7: =+AI4+AI5+AI6 -> 0 | AJ7: =+AJ4+AJ5+AJ6 -> 0 | AK7: =I7 -> RMB | AM7: I | AP7: second currency : | AQ7: =$P$52 -> EUR | AR7: rate : | AS7: ='RFQ Data'!K23 -> 8 | AT7: ='RFQ Data'!J23 -> EURRMB | AV7: =IF(AU7<>0,AU7,AS7) -> 8 | AW7: I | AX7: Final price (Sales target) | AY7: =AD7/$AV$7 -> 0 | AZ7: =AE7/$AV$7 -> 0 | BA7: =AF7/$AV$7 -> 0 | BB7: =AG7/$AV$7 -> 0 | BC7: =AH7/$AV$7 -> 0 | BD7: =AI7/$AV$7 -> 0 | BE7: =AJ7/$AV$7 -> 0 | BF7: =$P$52 -> EUR
A8: Sales (kRMB) | B8: 0 | C8: 666.56668 | D8: 666.56668 | E8: 666.56668 | F8: 666.56668 | G8: 666.56668 | H8: 0 | I8: 666.56668 | S8: I | AC8: =A8 -> Sales (kRMB) | AD8: =+AD7*AD2 -> 0 | AE8: =+AE7*AE2 -> 0 | AF8: =+AF7*AF2 -> 0 | AG8: =+AG7*AG2 -> 0 | AH8: =+AH7*AH2 -> 0 | AI8: =+AI7*AI2 -> 0 | AJ8: =+AJ7*AJ2 -> 0 | AK8: =AE8 -> 0 | AM8: I | AO8: EUR | AP8: RMB | AQ8: USD | AR8: INR | AS8: KWON | AU8: only used for simulation transposition | AW8: I | AX8: =+"Sales (k"&BF7&")" -> Sales (kEUR) | AY8: =AD8/$AV$7 -> 0 | AZ8: =AE8/$AV$7 -> 0 | BA8: =AF8/$AV$7 -> 0 | BB8: =AG8/$AV$7 -> 0 | BC8: =AH8/$AV$7 -> 0 | BD8: =AI8/$AV$7 -> 0 | BE8: =AJ8/$AV$7 -> 0 | BF8: =AZ8 -> 0
S9: I | AM9: I | AO9: ='RFQ Data'!H22 -> 0.125 | AP9: ='RFQ Data'!I22 -> 1 | AQ9: ='RFQ Data'!J22 -> 0.1375 | AR9: ='RFQ Data'!K22 -> 11.875 | AS9: ='RFQ Data'!L22 -> 0.195 | AU9: not take in account in costing | AW9: I
A10: RM incl. supplier productivity | B10: 0 | C10: 213.79154 | D10: 213.79154 | E10: 213.79154 | F10: 213.79154 | G10: 213.79154 | H10: 0 | I10: 213.79154 | S10: I | T10: Simulation at Target Price + Indexation changes + with vol effect at | Z10: =U49 -> 1.151916 | AA10: set up it below | AC10: RM incl. supplier productivity | AD10: =+(AE10+0)/AE$2*AD$2 -> 0 | AE10: =(C10/C$2++SUM(INDEX_IMPACT))*AE$2 -> 213.79154 | AF10: =(D10/D$2++SUM(INDEX_IMPACT))*AF$2 -> 213.79154 | AG10: =(E10/E$2++SUM(INDEX_IMPACT))*AG$2 -> 213.79154 | AH10: =(F10/F$2++SUM(INDEX_IMPACT))*AH$2 -> 213.79154 | AI10: =(G10/G$2++SUM(INDEX_IMPACT))*AI$2 -> 213.79154 | AJ10: =+AI10/AI$2*AJ$2 -> 0 | AK10: =AE10 -> 213.79154 | AM10: I | AU10: not impacted RM cost, … | AW10: I | AX10: RM incl. supplier productivity | AY10: =AD10/$AV$7 -> 0 | AZ10: =AE10/$AV$7 -> 26.723943 | BA10: =AF10/$AV$7 -> 26.723943 | BB10: =AG10/$AV$7 -> 26.723943 | BC10: =AH10/$AV$7 -> 26.723943 | BD10: =AI10/$AV$7 -> 26.723943 | BE10: =AJ10/$AV$7 -> 0 | BF10: =AZ10 -> 26.723943
A11: Packaging | B11: 0 | C11: 1.5223024 | D11: 1.5223024 | E11: 1.5223024 | F11: 1.5223024 | G11: 1.5223024 | H11: 0 | I11: 1.5223024 | S11: I | Z11: =$N$52 -> RMB | AA11: =$P$52 -> EUR | AC11: Packaging | AD11: =AE11/AE2*AD$2 -> 0 | AE11: =C11/C$2*AE$2 -> 1.5223024 | AF11: =D11/D$2*AF$2 -> 1.5223024 | AG11: =E11/E$2*AG$2 -> 1.5223024 | AH11: =F11/F$2*AH$2 -> 1.5223024 | AI11: =G11/G$2*AI$2 -> 1.5223024 | AJ11: =(AI11+0)/AI2*AJ$2 -> 0 | AK11: =AE11 -> 1.5223024 | AM11: I | AW11: I | AX11: Packaging | AY11: =AD11/$AV$7 -> 0 | AZ11: =AE11/$AV$7 -> 0.19028781 | BA11: =AF11/$AV$7 -> 0.19028781 | BB11: =AG11/$AV$7 -> 0.19028781 | BC11: =AH11/$AV$7 -> 0.19028781 | BD11: =AI11/$AV$7 -> 0.19028781 | BE11: =AJ11/$AV$7 -> 0 | BF11: =AZ11 -> 0.19028781
A12: Total Material | B12: 0 | C12: 215.31384 | D12: 215.31384 | E12: 215.31384 | F12: 215.31384 | G12: 215.31384 | H12: 0 | S12: I | T12: =IF(W7<>0,W7,W4) -> 0 | U12: =N52 -> RMB | V12: =Z12/$T$12 -> #DIV/0! | X12: RM + Packaging | Z12: =N43+SUM(INDEX_IMPACT) -> 0.43062769 | AA12: =Z12/$K$52 -> 0.053828461 | AC12: Total Material | AD12: =+AD10+AD11 -> 0 | AE12: =+AE10+AE11 -> 215.31384 | AF12: =+AF10+AF11 -> 215.31384 | AG12: =+AG10+AG11 -> 215.31384 | AH12: =+AH10+AH11 -> 215.31384 | AI12: =+AI10+AI11 -> 215.31384 | AJ12: =+AJ10+AJ11 -> 0 | AM12: I | AW12: I | AX12: Total Material | AY12: =AD12/$AV$7 -> 0 | AZ12: =AE12/$AV$7 -> 26.914231 | BA12: =AF12/$AV$7 -> 26.914231 | BB12: =AG12/$AV$7 -> 26.914231 | BC12: =AH12/$AV$7 -> 26.914231 | BD12: =AI12/$AV$7 -> 26.914231 | BE12: =AJ12/$AV$7 -> 0
B13: 0 | C13: 0.32073542 | D13: 0.32073542 | E13: 0.32073542 | F13: 0.32073542 | G13: 0.32073542 | H13: 0 | S13: I | V13: =(Z13+Z14+Z15)/$T$12 -> #DIV/0! | W13: DC | X13: DL | Z13: =N44 -> 0.060738826 | AA13: =Z13/$K$52 -> 0.0075923533 | AD13: =+IF(AD8<>0,AD10/AD8,0) -> 0 | AE13: =+IF(AE8<>0,AE10/AE8,0) -> 0 | AF13: =+IF(AF8<>0,AF10/AF8,0) -> 0 | AG13: =+IF(AG8<>0,AG10/AG8,0) -> 0 | AH13: =+IF(AH8<>0,AH10/AH8,0) -> 0 | AI13: =+IF(AI8<>0,AI10/AI8,0) -> 0 | AJ13: =+IF(AJ8<>0,AJ10/AJ8,0) -> 0 | AM13: I | AW13: I | AY13: =AD13 -> 0 | AZ13: =AE13 -> 0 | BA13: =AF13 -> 0 | BB13: =AG13 -> 0 | BC13: =AH13 -> 0 | BD13: =AI13 -> 0 | BE13: =AJ13 -> 0
S14: I | T14: =T12/K52 -> 0 | U14: =P52 -> EUR | X14: VOH | Z14: =N45 -> 0.1368822 | AA14: =Z14/$K$52 -> 0.017110275 | AM14: I | AW14: I
A15: DL | B15: 0 | C15: 30.369413 | D15: 30.369413 | E15: 30.369413 | F15: 30.369413 | G15: 30.369413 | H15: 0 | I15: 30.369413 | S15: I | X15: tranportation | Z15: =N46 -> 0.1548453 | AA15: =Z15/$K$52 -> 0.019355663 | AC15: DL | AD15: =+AE15/AE$2*AD$2 -> 0 | AE15: =C15/C$2*AE$2 -> 30.369413 | AF15: =D15/D$2*AF$2 -> 30.369413 | AG15: =E15/E$2*AG$2 -> 30.369413 | AH15: =F15/F$2*AH$2 -> 30.369413 | AI15: =+AH15/AH$2*AI$2 -> 30.369413 | AJ15: =+AI15/AI$2*AJ$2 -> 0 | AK15: =AE15 -> 30.369413 | AM15: I | AW15: I | AX15: DL | AY15: =AD15/$AV$7 -> 0 | AZ15: =AE15/$AV$7 -> 3.7961766 | BA15: =AF15/$AV$7 -> 3.7961766 | BB15: =AG15/$AV$7 -> 3.7961766 | BC15: =AH15/$AV$7 -> 3.7961766 | BD15: =AI15/$AV$7 -> 3.7961766 | BE15: =AJ15/$AV$7 -> 0 | BF15: =AZ15 -> 3.7961766
B16: 0 | C16: 0.045560953 | D16: 0.045560953 | E16: 0.045560953 | F16: 0.045560953 | G16: 0.045560953 | H16: 0 | S16: I | V16: =(Z16+Z17+Z18)/$T$12 -> #DIV/0! | W16: GMDC | X16: FOH + Admin | Z16: =Y47 -> 0.19868335 | AA16: =Z16/$K$52 -> 0.024835419 | AD16: =+IF(AD$8<>0,AD15/AD$8,0) -> 0 | AE16: =+IF(AE$8<>0,AE15/AE$8,0) -> 0 | AF16: =+IF(AF$8<>0,AF15/AF$8,0) -> 0 | AG16: =+IF(AG$8<>0,AG15/AG$8,0) -> 0 | AH16: =+IF(AH$8<>0,AH15/AH$8,0) -> 0 | AI16: =+IF(AI$8<>0,AI15/AI$8,0) -> 0 | AJ16: =+IF(AJ$8<>0,AJ15/AJ$8,0) -> 0 | AM16: I | AW16: I | AY16: =AD16 -> 0 | AZ16: =AE16 -> 0 | BA16: =AF16 -> 0 | BB16: =AG16 -> 0 | BC16: =AH16 -> 0 | BD16: =AI16 -> 0 | BE16: =AJ16 -> 0
A17: VOH | B17: 0 | C17: 68.4411 | D17: 68.4411 | E17: 68.4411 | F17: 68.4411 | G17: 68.4411 | H17: 0 | I17: 68.4411 | S17: I | X17: Fees | Z17: =Y48 -> 0.13113101 | AA17: =Z17/$K$52 -> 0.016391376 | AC17: VOH | AD17: =+AE17/AE$2*AD$2 -> 0 | AE17: =C17/C$2*AE$2 -> 68.4411 | AF17: =D17/D$2*AF$2 -> 68.4411 | AG17: =E17/E$2*AG$2 -> 68.4411 | AH17: =F17/F$2*AH$2 -> 68.4411 | AI17: =+AH17/AH$2*AI$2 -> 68.4411 | AJ17: =+AI17/AI$2*AJ$2 -> 0 | AK17: =AE17 -> 68.4411 | AM17: I | AW17: I | AX17: VOH | AY17: =AD17/$AV$7 -> 0 | AZ17: =AE17/$AV$7 -> 8.5551375 | BA17: =AF17/$AV$7 -> 8.5551375 | BB17: =AG17/$AV$7 -> 8.5551375 | BC17: =AH17/$AV$7 -> 8.5551375 | BD17: =AI17/$AV$7 -> 8.5551375 | BE17: =AJ17/$AV$7 -> 0 | BF17: =AZ17 -> 8.5551375
B18: 0 | C18: 0.10267705 | D18: 0.10267705 | E18: 0.10267705 | F18: 0.10267705 | G18: 0.10267705 | H18: 0 | S18: I | X18: EBITDA | Z18: =T12-SUM(Z12:Z17) -> -1.1129084 | AA18: =Z18/$K$52 -> -0.13911355 | AD18: =+IF(AD$8<>0,AD17/AD$8,0) -> 0 | AE18: =+IF(AE$8<>0,AE17/AE$8,0) -> 0 | AF18: =+IF(AF$8<>0,AF17/AF$8,0) -> 0 | AG18: =+IF(AG$8<>0,AG17/AG$8,0) -> 0 | AH18: =+IF(AH$8<>0,AH17/AH$8,0) -> 0 | AI18: =+IF(AI$8<>0,AI17/AI$8,0) -> 0 | AJ18: =+IF(AJ$8<>0,AJ17/AJ$8,0) -> 0 | AM18: I | AW18: I | AY18: =AD18 -> 0 | AZ18: =AE18 -> 0 | BA18: =AF18 -> 0 | BB18: =AG18 -> 0 | BC18: =AH18 -> 0 | BD18: =AI18 -> 0 | BE18: =AJ18 -> 0
A19: Inbound transportation | B19: 0 | C19: 27.932041 | D19: 27.932041 | E19: 27.932041 | F19: 27.932041 | G19: 27.932041 | H19: 0 | S19: I | AC19: Inbound transportation | AD19: =+AE19/AE$2*AD$2 -> 0 | AE19: =C19/C$2*AE$2 -> 27.932041 | AF19: =D19/D$2*AF$2 -> 27.932041 | AG19: =E19/E$2*AG$2 -> 27.932041 | AH19: =F19/F$2*AH$2 -> 27.932041 | AI19: =+AH19/AH$2*AI$2 -> 27.932041 | AJ19: =+AI19/AI$2*AJ$2 -> 0 | AM19: I | AW19: I | AX19: Inbound transportation | AY19: =AD19/$AV$7 -> 0 | AZ19: =AE19/$AV$7 -> 3.4915052 | BA19: =AF19/$AV$7 -> 3.4915052 | BB19: =AG19/$AV$7 -> 3.4915052 | BC19: =AH19/$AV$7 -> 3.4915052 | BD19: =AI19/$AV$7 -> 3.4915052 | BE19: =AJ19/$AV$7 -> 0
A20: Outbound Transportation | B20: 0 | C20: 49.49061 | D20: 49.49061 | E20: 49.49061 | F20: 49.49061 | G20: 49.49061 | H20: 0 | S20: I | AC20: Outbound Transportation | AD20: =+AE20/AE$2*AD$2 -> 0 | AE20: =C20/C$2*AE$2 -> 49.49061 | AF20: =D20/D$2*AF$2 -> 49.49061 | AG20: =E20/E$2*AG$2 -> 49.49061 | AH20: =F20/F$2*AH$2 -> 49.49061 | AI20: =+AH20/AH$2*AI$2 -> 49.49061 | AJ20: =+AI20/AI$2*AJ$2 -> 0 | AM20: I | AW20: I | AX20: Outbound Transportation | AY20: =AD20/$AV$7 -> 0 | AZ20: =AE20/$AV$7 -> 6.1863262 | BA20: =AF20/$AV$7 -> 6.1863262 | BB20: =AG20/$AV$7 -> 6.1863262 | BC20: =AH20/$AV$7 -> 6.1863262 | BD20: =AI20/$AV$7 -> 6.1863262 | BE20: =AJ20/$AV$7 -> 0
A21: Total transportation | B21: 0 | C21: 77.422651 | D21: 77.422651 | E21: 77.422651 | F21: 77.422651 | G21: 77.422651 | H21: 0 | I21: 77.422651 | S21: I | AC21: Total transportation | AD21: =+AD19+AD20 -> 0 | AE21: =+AE19+AE20 -> 77.422651 | AF21: =+AF19+AF20 -> 77.422651 | AG21: =+AG19+AG20 -> 77.422651 | AH21: =+AH19+AH20 -> 77.422651 | AI21: =+AI19+AI20 -> 77.422651 | AJ21: =+AJ19+AJ20 -> 0 | AK21: =AE21 -> 77.422651 | AM21: I | AW21: I | AX21: Total transportation | AY21: =AD21/$AV$7 -> 0 | AZ21: =AE21/$AV$7 -> 9.6778314 | BA21: =AF21/$AV$7 -> 9.6778314 | BB21: =AG21/$AV$7 -> 9.6778314 | BC21: =AH21/$AV$7 -> 9.6778314 | BD21: =AI21/$AV$7 -> 9.6778314 | BE21: =AJ21/$AV$7 -> 0 | BF21: =AZ21 -> 9.6778314
B22: 0 | C22: 0.1161514 | D22: 0.1161514 | E22: 0.1161514 | F22: 0.1161514 | G22: 0.1161514 | H22: 0 | S22: I | AD22: =+IF(AD$8<>0,AD21/AD$8,0) -> 0 | AE22: =+IF(AE$8<>0,AE21/AE$8,0) -> 0 | AF22: =+IF(AF$8<>0,AF21/AF$8,0) -> 0 | AG22: =+IF(AG$8<>0,AG21/AG$8,0) -> 0 | AH22: =+IF(AH$8<>0,AH21/AH$8,0) -> 0 | AI22: =+IF(AI$8<>0,AI21/AI$8,0) -> 0 | AJ22: =+IF(AJ$8<>0,AJ21/AJ$8,0) -> 0 | AM22: I | AW22: I | AY22: =AD22 -> 0 | AZ22: =AE22 -> 0 | BA22: =AF22 -> 0 | BB22: =AG22 -> 0 | BC22: =AH22 -> 0 | BD22: =AI22 -> 0 | BE22: =AJ22 -> 0
S23: I | AM23: I | AW23: I
A24: GMDC | B24: 0 | C24: 275.01967 | D24: 275.01967 | E24: 275.01967 | F24: 275.01967 | G24: 275.01967 | H24: 0 | I24: 275.01967 | S24: I | AC24: GMDC | AD24: =+AD8-AD10-AD15-AD17-AD21-AD11 -> 0 | AE24: =+AE8-AE10-AE15-AE17-AE21-AE11 -> -391.54701 | AF24: =+AF8-AF10-AF15-AF17-AF21-AF11 -> -391.54701 | AG24: =+AG8-AG10-AG15-AG17-AG21-AG11 -> -391.54701 | AH24: =+AH8-AH10-AH15-AH17-AH21-AH11 -> -391.54701 | AI24: =+AI8-AI10-AI15-AI17-AI21-AI11 -> -391.54701 | AJ24: =+AJ8-AJ10-AJ15-AJ17-AJ21 -> 0 | AK24: =AE24 -> -391.54701 | AM24: I | AW24: I | AX24: GMDC | AY24: =AD24/$AV$7 -> 0 | AZ24: =AE24/$AV$7 -> -48.943376 | BA24: =AF24/$AV$7 -> -48.943376 | BB24: =AG24/$AV$7 -> -48.943376 | BC24: =AH24/$AV$7 -> -48.943376 | BD24: =AI24/$AV$7 -> -48.943376 | BE24: =AJ24/$AV$7 -> 0 | BF24: =AZ24 -> -48.943376
B25: 0 | C25: 0.41259139 | D25: 0.41259139 | E25: 0.41259139 | F25: 0.41259139 | G25: 0.41259139 | H25: 0 | S25: I | AD25: =+IF(AD$8<>0,AD24/AD$8,0) -> 0 | AE25: =+IF(AE$8<>0,AE24/AE$8,0) -> 0 | AF25: =+IF(AF$8<>0,AF24/AF$8,0) -> 0 | AG25: =+IF(AG$8<>0,AG24/AG$8,0) -> 0 | AH25: =+IF(AH$8<>0,AH24/AH$8,0) -> 0 | AI25: =+IF(AI$8<>0,AI24/AI$8,0) -> 0 | AJ25: =+IF(AJ$8<>0,AJ24/AJ$8,0) -> 0 | AM25: I | AW25: I | AY25: =AD25 -> 0 | AZ25: =AE25 -> 0 | BA25: =AF25 -> 0 | BB25: =AG25 -> 0 | BC25: =AH25 -> 0 | BD25: =AI25 -> 0 | BE25: =AJ25 -> 0
S26: I | AM26: I | AW26: I
A27: FOH + Admin | B27: 0 | C27: 99.341675 | D27: 99.341675 | E27: 99.341675 | F27: 99.341675 | G27: 99.341675 | H27: 0 | I27: 99.341675 | S27: I | AC27: FOH + Admin | AD27: =$Z$16*AD$2 -> 0 | AE27: =$Z$16*AE$2 -> 99.341675 | AF27: =$Z$16*AF$2 -> 99.341675 | AG27: =$Z$16*AG$2 -> 99.341675 | AH27: =$Z$16*AH$2 -> 99.341675 | AI27: =$Z$16*AI$2 -> 99.341675 | AJ27: =$Z$16*AJ$2 -> 0 | AK27: =AE27 -> 99.341675 | AM27: I | AW27: I | AX27: FOH + Admin | AY27: =AD27/$AV$7 -> 0 | AZ27: =AE27/$AV$7 -> 12.417709 | BA27: =AF27/$AV$7 -> 12.417709 | BB27: =AG27/$AV$7 -> 12.417709 | BC27: =AH27/$AV$7 -> 12.417709 | BD27: =AI27/$AV$7 -> 12.417709 | BE27: =AJ27/$AV$7 -> 0 | BF27: =AZ27 -> 12.417709
B28: 0 | C28: 0.14903486 | D28: 0.14903486 | E28: 0.14903486 | F28: 0.14903486 | G28: 0.14903486 | H28: 0 | S28: I | AD28: =+IF(AD$8<>0,AD27/AD$8,0) -> 0 | AE28: =+IF(AE$8<>0,AE27/AE$8,0) -> 0 | AF28: =+IF(AF$8<>0,AF27/AF$8,0) -> 0 | AG28: =+IF(AG$8<>0,AG27/AG$8,0) -> 0 | AH28: =+IF(AH$8<>0,AH27/AH$8,0) -> 0 | AI28: =+IF(AI$8<>0,AI27/AI$8,0) -> 0 | AJ28: =+IF(AJ$8<>0,AJ27/AJ$8,0) -> 0 | AM28: I | AW28: I | AY28: =AD28 -> 0 | AZ28: =AE28 -> 0 | BA28: =AF28 -> 0 | BB28: =AG28 -> 0 | BC28: =AH28 -> 0 | BD28: =AI28 -> 0 | BE28: =AJ28 -> 0
A29: Fees | B29: 0 | C29: 65.565505 | D29: 65.565505 | E29: 65.565505 | F29: 65.565505 | G29: 65.565505 | H29: 0 | I29: 65.565505 | S29: I | AC29: Fees | AD29: =$Z$17*AD$2 -> 0 | AE29: =$Z$17*AE$2 -> 65.565505 | AF29: =$Z$17*AF$2 -> 65.565505 | AG29: =$Z$17*AG$2 -> 65.565505 | AH29: =$Z$17*AH$2 -> 65.565505 | AI29: =$Z$17*AI$2 -> 65.565505 | AJ29: =$Z$17*AJ$2 -> 0 | AK29: =AE29 -> 65.565505 | AM29: I | AW29: I | AX29: Fees | AY29: 0.0290778 | AZ29: 0.0290778 | BA29: 0.0290778 | BB29: 0.0290778 | BC29: 0.0290778 | BD29: 0.0290778 | BE29: 0.0290778 | BF29: =AZ29 -> 0.0290778
B30: 0 | C30: 0.09836301 | D30: 0.09836301 | E30: 0.09836301 | F30: 0.09836301 | G30: 0.09836301 | H30: 0 | S30: I | AD30: =+IF(AD$8<>0,AD29/AD$8,0) -> 0 | AE30: =+IF(AE$8<>0,AE29/AE$8,0) -> 0 | AF30: =+IF(AF$8<>0,AF29/AF$8,0) -> 0 | AG30: =+IF(AG$8<>0,AG29/AG$8,0) -> 0 | AH30: =+IF(AH$8<>0,AH29/AH$8,0) -> 0 | AI30: =+IF(AI$8<>0,AI29/AI$8,0) -> 0 | AJ30: =+IF(AJ$8<>0,AJ29/AJ$8,0) -> 0 | AM30: I | AW30: I | AY30: =AD30 -> 0 | AZ30: =AE30 -> 0 | BA30: =AF30 -> 0 | BB30: =AG30 -> 0 | BC30: =AH30 -> 0 | BD30: =AI30 -> 0 | BE30: =AJ30 -> 0
S31: I | AM31: I | AW31: I
A32: EBITDA | B32: 0 | C32: 110.11249 | D32: 110.11249 | E32: 110.11249 | F32: 110.11249 | G32: 110.11249 | H32: 0 | I32: 110.11249 | S32: I | AC32: EBITDA | AD32: =+AD24-AD27-AD29 -> 0 | AE32: =+AE24-AE27-AE29 -> -556.45419 | AF32: =+AF24-AF27-AF29 -> -556.45419 | AG32: =+AG24-AG27-AG29 -> -556.45419 | AH32: =+AH24-AH27-AH29 -> -556.45419 | AI32: =+AI24-AI27-AI29 -> -556.45419 | AJ32: =+AJ24-AJ27-AJ29 -> 0 | AK32: =AE32 -> -556.45419 | AM32: I | AW32: I | AX32: EBITDA | AY32: =AD32/$AV$7 -> 0 | AZ32: =AE32/$AV$7 -> -69.556774 | BA32: =AF32/$AV$7 -> -69.556774 | BB32: =AG32/$AV$7 -> -69.556774 | BC32: =AH32/$AV$7 -> -69.556774 | BD32: =AI32/$AV$7 -> -69.556774 | BE32: =AJ32/$AV$7 -> 0 | BF32: =AZ32 -> -69.556774
B33: 0 | C33: 0.16519352 | D33: 0.16519352 | E33: 0.16519352 | F33: 0.16519352 | G33: 0.16519352 | H33: 0 | S33: I | AD33: =+IF(AD$8<>0,AD32/AD$8,0) -> 0 | AE33: =+IF(AE$8<>0,AE32/AE$8,0) -> 0 | AF33: =+IF(AF$8<>0,AF32/AF$8,0) -> 0 | AG33: =+IF(AG$8<>0,AG32/AG$8,0) -> 0 | AH33: =+IF(AH$8<>0,AH32/AH$8,0) -> 0 | AI33: =+IF(AI$8<>0,AI32/AI$8,0) -> 0 | AJ33: =+IF(AJ$8<>0,AJ32/AJ$8,0) -> 0 | AM33: I | AW33: I | AY33: =AD33 -> 0 | AZ33: =AE33 -> 0 | BA33: =AF33 -> 0 | BB33: =AG33 -> 0 | BC33: =AH33 -> 0 | BD33: =AI33 -> 0 | BE33: =AJ33 -> 0
S34: I | AM34: I | AW34: I
A35: Depreciation | B35: 0 | C35: 15.985764 | D35: 15.985764 | E35: 15.985764 | F35: 15.985764 | G35: 15.985764 | H35: 0 | I35: 15.985764 | S35: I | AC35: Depreciation | AD35: =+AD66 -> 0 | AE35: =+AE66 -> 15.985764 | AF35: =+AF66 -> 15.985764 | AG35: =+AG66 -> 15.985764 | AH35: =+AH66 -> 15.985764 | AI35: =+AI66 -> 15.985764 | AJ35: =+AJ66 -> 0 | AK35: =AE35 -> 15.985764 | AM35: I | AW35: I | AX35: Depreciation | AY35: =AD35/$AV$7 -> 0 | AZ35: =AE35/$AV$7 -> 1.9982204 | BA35: =AF35/$AV$7 -> 1.9982204 | BB35: =AG35/$AV$7 -> 1.9982204 | BC35: =AH35/$AV$7 -> 1.9982204 | BD35: =AI35/$AV$7 -> 1.9982204 | BE35: =AJ35/$AV$7 -> 0 | BF35: =AZ35 -> 1.9982204
A36: Financial cost | B36: 0 | C36: 0.1 | D36: 15.170731 | E36: 9.9065372 | F36: 4.3659736 | G36: -1.4654695 | H36: -7.6030634 | I36: 0.1 | S36: I | AC36: Financial cost | AD36: =-AD51 -> 0 | AE36: =-AE51 -> #DIV/0! | AF36: =-AF51 -> #DIV/0! | AG36: =-AG51 -> #DIV/0! | AH36: =-AH51 -> #DIV/0! | AI36: =-AI51 -> #DIV/0! | AJ36: =-AJ51 -> #DIV/0! | AK36: =AE36 -> #DIV/0! | AM36: I | AW36: I | AX36: Financial cost | AY36: =AD36/$AV$7 -> 0 | AZ36: =AE36/$AV$7 -> #DIV/0! | BA36: =AF36/$AV$7 -> #DIV/0! | BB36: =AG36/$AV$7 -> #DIV/0! | BC36: =AH36/$AV$7 -> #DIV/0! | BD36: =AI36/$AV$7 -> #DIV/0! | BE36: =AJ36/$AV$7 -> #DIV/0! | BF36: =AZ36 -> #DIV/0!
K37: Parameter box | M37: 1.4379586 | S37: I | W37: min price / max vol (without silver): | X37: =M37 -> 1.4379586 | AM37: I | AW37: I
A38: Operation Income | B38: 0 | C38: 94.02673 | D38: 78.955999 | E38: 84.220193 | F38: 89.760756 | G38: 95.5922 | H38: 7.6030634 | I38: 94.02673 | S38: I | AC38: Operatin Income | AD38: =+AD32-AD35-AD36 -> 0 | AE38: =+AE32-AE35-AE36 -> #DIV/0! | AF38: =+AF32-AF35-AF36 -> #DIV/0! | AG38: =+AG32-AG35-AG36 -> #DIV/0! | AH38: =+AH32-AH35-AH36 -> #DIV/0! | AI38: =+AI32-AI35-AI36 -> #DIV/0! | AJ38: =+AJ32-AJ35-AJ36 -> #DIV/0! | AK38: =AE38 -> #DIV/0! | AM38: I | AW38: I | AX38: Operatin Income | AY38: =AD38/$AV$7 -> 0 | AZ38: =AE38/$AV$7 -> #DIV/0! | BA38: =AF38/$AV$7 -> #DIV/0! | BB38: =AG38/$AV$7 -> #DIV/0! | BC38: =AH38/$AV$7 -> #DIV/0! | BD38: =AI38/$AV$7 -> #DIV/0! | BE38: =AJ38/$AV$7 -> #DIV/0! | BF38: =AZ38 -> #DIV/0!
B39: 0 | C39: 0.14106125 | D39: 0.11845176 | E39: 0.12634924 | F39: 0.13466133 | G39: 0.14340981 | H39: 0 | S39: I | AD39: =+IF(AD$8<>0,AD38/AD$8,0) -> 0 | AE39: =+IF(AE$8<>0,AE38/AE$8,0) -> 0 | AF39: =+IF(AF$8<>0,AF38/AF$8,0) -> 0 | AG39: =+IF(AG$8<>0,AG38/AG$8,0) -> 0 | AH39: =+IF(AH$8<>0,AH38/AH$8,0) -> 0 | AI39: =+IF(AI$8<>0,AI38/AI$8,0) -> 0 | AJ39: =+IF(AJ$8<>0,AJ38/AJ$8,0) -> 0 | AM39: I | AW39: I | AY39: =AD39 -> 0 | AZ39: =AE39 -> 0 | BA39: =AF39 -> 0 | BB39: =AG39 -> 0 | BC39: =AH39 -> 0 | BD39: =AI39 -> 0 | BE39: =AJ39 -> 0
K40: Initial SCENARIO for a package volume of : | O40: 500 | P40: Kparts | S40: I | T40: LOOK FOR PACKAGE OFFER or ANOTHER SCENARIO | AA40: to be validated with VP Sales | AM40: I | AW40: I
...

Sheet PROCESS & CAPEX
A1: BOM, PROCESS details & CAPEX - Costing process | K1: Riyong/RY5.578.100A Riyong China | L1: Area with fomula
A2: Productivity proposed | B2: 2025 | C2: 2026 | D2: 2027 | E2: 2028 | F2: 2029 | G2: 2030 | H2: RFQ# | K2: 25626-BRU-00
A3: Price/piece RMB | B3: 1.3331334 | C3: 1.3331334 | D3: 1.3331334 | E3: 1.3331334 | F3: 1.3331334 | G3: 1.3331334 | K3: #VALUE!
A4: Qty | B4: 0 | C4: 500 | D4: 500 | E4: 500 | F4: 500 | G4: 500
A6: Business link max | B6: 0 | C6: kRMB | I6: volume effect
A7: Incoterm | B7: recommended : | C7: DDP | D7: China | E7: Quoted : | F7: EXW | G7: Tianjin | I7: 1.151916
A8: Payment terms max | B8: 60 | C8: Net | F8: rate
A9: Invoicing currency | B9: RMB | E9: RMBRMB | F9: 1 | G9: RMB
A11: Indexation on material | C11: RMB | D11: RMB | K11: used | L11: changed | M11: impact / u | N11: new value
A12: Material | B12: Weight in g | C12: Material value /kg | D12: Value in the product | K12: EUR/kg | L12: EUR/kg | M12: =B9 -> RMB | N12: =M12 -> RMB
A13: Copper | B13: 3.1101917 | C13: 69.2 | D13: 0.22419299 | K13: 8.65 | M13: =IF(L13=0,0,(L13*'RFQ Data'!$K$24-C13)*B13/1000) -> 0 | N13: =D13+M13 -> 0.22419299
A14: Silver | B14: 0 | C14: 9096 | D14: 0 | K14: 1137 | M14: =IF(L14=0,0,(L14*'RFQ Data'!$K$24-C14)*B14/1000) -> 0 | N14: =D14+M14 -> 0
A15: Nat Graphite | B15: 3.8565968 | C15: 22.211227 | D15: 0.089228904 | K15: 2.7764034 | M15: =IF(L15=0,0,(L15*'RFQ Data'!$K$24-C15)*B15/1000) -> 0 | N15: =D15+M15 -> 0.089228904
A16: Art Graphite | B16: 0 | C16: 60 | D16: 0 | K16: 7.5 | M16: =IF(L16=0,0,(L16*'RFQ Data'!$K$24-C16)*B16/1000) -> 0 | N16: =D16+M16 -> 0
A17: - | B17: 0 | C17: 0 | D17: 0 | K17: 0 | M17: =IF(L17=0,0,(L17*'RFQ Data'!$K$24-C17)*B17/1000) -> 0 | N17: =D17+M17 -> 0
A18: Other mix | B18: 0 | C18: 176 | D18: 0 | K18: 22 | M18: =IF(L18=0,0,(L18*'RFQ Data'!$K$24-C18)*B18/1000) -> 0 | N18: =D18+M18 -> 0
A19: 0 | B19: 0 | M19: =IF(L19=0,0,(L19*'RFQ Data'!$K$24-C19)*B19/1000) -> 0 | N19: =D19+M19 -> #VALUE!
A20: Indexation on exchange rate | D20: RMB
A21: Purchasing currency | B21: Quoting currency | C21: Exchange rate | D21: Value
A22: EUR | B22: RMB | C22: 8 | D22: 0.37269761
A23: RMB | B23: RMB | C23: 1 | D23: 0.090907272
A24: 0 | B24: RMB | C24: 0 | D24: 0
C25: 0 | D25: 0
C26: 0 | D26: 0
L27: New indexations are taking in account in the profitability simulation
A28: Material cost | E28: 0.42758308 | F28: RMB | H28: CAPEX COST | J28: Margin | L28: Customer PRICE
D29: Scrap | E29: 0.018544195 | F29: RMB | I29: KRMB | J29: 0.1 | M29: =I29 -> KRMB
A30: Description | B30: Comment (imposed supplier; internal?,…) | C30: Qty per product | D30: Plant (user) | E30: Cost | F30: origin of incoterm | I30: TOOLING | K30: needs ? | M30: TOOLING | N30: COMMENT
A31: Copper powder (g) | B31: 0 | C31: 2.332717 | D31: Tianjin | E31: 0.16142402 | F31: Europe | M31: =IF(AND(K31<>0,ISNUMBER(I31)),I31*(1+J$29),"")
A32: Silver powder (g) | B32: 0 | C32: 0 | E32: 0 | F32: Europe | M32: =IF(AND(K32<>0,ISNUMBER(I32)),I32*(1+J$29),"")
A33: Mix with Nat Graphite (g) | B33: 0 | C33: 3.7045768 | D33: Frankfurt | E33: 0.094650661 | M33: =IF(AND(K33<>0,ISNUMBER(I33)),I33*(1+J$29),"")
A34: Mix with Art Graphite (g) | B34: 0 | C34: 0 | E34: 0 | M34: =IF(AND(K34<>0,ISNUMBER(I34)),I34*(1+J$29),"")
A35: Cu/Ag powder conversion (g) | B35: 0 | C35: 2.332717 | D35: Tianjin | E35: 0.055985209 | F35: Europe | M35: =IF(AND(K35<>0,ISNUMBER(I35)),I35*(1+J$29),"")
A36: Other mix (g) | B36: 0 | C36: 0 | E36: 0 | F36: Europe | M36: =IF(AND(K36<>0,ISNUMBER(I36)),I36*(1+J$29),"")
A37: impregnation material (g) | B37: 0 | C37: 0 | E37: 0 | M37: =IF(AND(K37<>0,ISNUMBER(I37)),I37*(1+J$29),"")
A38: Cable-material (g) | B38: 0 | C38: 0.68175 | D38: Tianjin | E38: 0.0471771 | F38: China + South pacific | M38: =IF(AND(K38<>0,ISNUMBER(I38)),I38*(1+J$29),"")
A39: Cable-conversion (g) | B39: 0 | C39: 0.68175 | D39: Tianjin | E39: 0.0369963 | F39: China + South pacific | M39: =IF(AND(K39<>0,ISNUMBER(I39)),I39*(1+J$29),"")
A40: Grade from Plate | B40: 0 | C40: 0 | E40: 0 | F40: Europe | M40: =IF(AND(K40<>0,ISNUMBER(I40)),I40*(1+J$29),"")
A41: Sleeves (mm) | B41: 0 | C41: 0 | E41: 0 | F41: China + South pacific | I41: 0 | M41: =IF(AND(K41<>0,ISNUMBER(I41)),I41*(1+J$29),"")
A42: specific terminal 1 | B42: 0 | C42: 0 | E42: 0 | F42: China + South pacific | I42: 8.125 | K42: x | M42: =IF(AND(K42<>0,ISNUMBER(I42)),I42*(1+J$29),"") -> 8.9375
...

Sheet Small runner-PRICE
B1: This area will be used as costing if this RFQ is concerned by a small runner or MOQ change | H1: MOQ/order and minimum price
B2: PRICE Simulator for small series | H2: Pricing by annual volume (as costing file), is mostly efficient for more than 1 full batch (full oven) by year.
C3: complete the yellow cell only | H3: Standard MOQ is defined as a batch oven. Lower MOQ can be offered but in this case std GMDC calcualation is not relevant.
C4: Select the Currency | D4: Simulate your Brush : | H4: Find below the costing tool for minimim price versus MOQ (depending of applicattion & brush size)
C5: EUR | D5: t (mm) | E5: ='PROCESS & CAPEX'!I94 -> 7 | H5: Assumption is that no order can be less than | J5: 2100 | K5: Eur | L5: (Target 2500 Eur /invoice)
C6: =HLOOKUP(C5,$J$7:$N$8,2,0)/J8 -> 1 | D6: a (mm) | E6: ='PROCESS & CAPEX'!I95 -> 10 | I6: Currency rate
D7: r (mm) | E7: ='PROCESS & CAPEX'!I96 -> 28 | J7: EUR | K7: RMB | L7: USD | M7: INR | N7: KWON
F8: if you want to balance a other price/u | I8: =QuotingCUR -> RMB | J8: ='RFQ Data'!H22 -> 0.125 | K8: ='RFQ Data'!I22 -> 1 | L8: ='RFQ Data'!J22 -> 0.1375 | M8: ='RFQ Data'!K22 -> 11.875 | N8: ='RFQ Data'!L22 -> 0.195
D9: Price without components | E9: =IF(F9<>"",F9,(PRICE_inCUR-SUM(D10:D15))*_xlfn.XLOOKUP(C5,J7:N7,J8:N8,1,0,)) -> 0.16664167
C10: Sleeves (mm) | D10: ='PROCESS & CAPEX'!E41*Cur_rate -> 0 | E10: =D10*1.2 -> 0 | F10: +margin (20%)
C11: specific terminal 1 | D11: ='PROCESS & CAPEX'!E42*Cur_rate -> 0 | E11: =D11*1.2 -> 0 | F11: "
C12: specific terminal 2 | D12: ='PROCESS & CAPEX'!E43*Cur_rate -> 0 | E12: =D12*1.2 -> 0 | F12: "
C13: Spring | D13: ='PROCESS & CAPEX'!E44*Cur_rate -> 0 | E13: =D13*1.2 -> 0 | F13: "
C14: Pop off (sub-assembly) | D14: ='PROCESS & CAPEX'!E45*Cur_rate -> 0 | E14: =D14*1.2 -> 0 | F14: "
C15: Alarm wire | D15: ='PROCESS & CAPEX'!E46*Cur_rate -> 0 | E15: =D15*1.2 -> 0 | F15: "
D17: V = | E17: =E7*E6*E5/1000 -> 1.96 | F17: cm3
C18: Full batch (oven) | D18: Standard MOQ | E18: =PRICE!N53 -> 13000 | F18: =0.4/E17*60000 -> 12244.898
B19: 0.9 | C19: of batch size as limit of use of SR tool | D19: Min price is | E19: =PRICE_inCUR*Cur_rate -> 1.3331334 | F19: =C5 -> EUR
E20: =IF(E9<>0,E9,(E17^$D$37/$D$38)*(Cur_rate)) -> 0.16664167 | F20: =E20*F18 -> 2040.5103
B21: {=J5*Cur_rate} -> 2100 | C21: =C5&" min must be offered" -> EUR min must be offered | D21: MOQ /order | E21: PRICE/u | F21: min /order (Cur)
C22: fix your small series qty | D22: 120000 | E22: =IF(F22="from costing","Serial price",(F22/$D22)*1) -> Serial price | F22: =IF($D22>=F$18*$B$19,"from costing",F$29*2+LN($D22/$D$29)*(F$20-F$29*2)/LN(F$18/$D$29)+SUM($E$10:$E$15)*D22) -> from costing | I22: check here
C23: fix your small series qty | D23: =D22/2 -> 60000 | E23: =IF(F23="from costing","Serial price",(F23/$D23)*1) -> Serial price | F23: =IF($D23>=F$18*$B$19,"from costing",F$29*2+LN($D23/$D$29)*(F$20-F$29*2)/LN(F$18/$D$29)+SUM($E$10:$E$15)*D23) -> from costing | I23: which min price to use
C24: fix your small series qty | D24: =D23/3 -> 20000 | E24: =IF(F24="from costing","Serial price",(F24/$D24)*1) -> Serial price | F24: =IF($D24>=F$18*$B$19,"from costing",F$29*2+LN($D24/$D$29)*(F$20-F$29*2)/LN(F$18/$D$29)+SUM($E$10:$E$15)*D24) -> from costing
C25: fix your small series qty | D25: =D24/2 -> 10000 | E25: =IF(F25="from costing","Serial price",(F25/$D25)*1) -> 0.19511463 | F25: =IF($D25>=F$18*$B$19,"from costing",F$29*2+LN($D25/$D$29)*(F$20-F$29*2)/LN(F$18/$D$29)+SUM($E$10:$E$15)*D25) -> 1951.1463
C26: fix your small series qty | D26: =D25/2 -> 5000 | E26: =IF(F26="from costing","Serial price",(F26/$D26)*1) -> 0.32905897 | F26: =IF($D26>=F$18*$B$19,"from costing",F$29*2+LN($D26/$D$29)*(F$20-F$29*2)/LN(F$18/$D$29)+SUM($E$10:$E$15)*D26) -> 1645.2948
C27: fix your small series qty | D27: =D26/2 -> 2500 | E27: =IF(F27="from costing","Serial price",(F27/$D27)*1) -> 0.53577734 | F27: =IF($D27>=F$18*$B$19,"from costing",F$29*2+LN($D27/$D$29)*(F$20-F$29*2)/LN(F$18/$D$29)+SUM($E$10:$E$15)*D27) -> 1339.4433
C28: fix your small series qty | D28: =D27/2.5 -> 1000 | E28: =IF(F28="from costing","Serial price",(F28/$D28)*1) -> 0.93512967 | F28: =IF($D28>=F$18*$B$19,"from costing",F$29*2+LN($D28/$D$29)*(F$20-F$29*2)/LN(F$18/$D$29)+SUM($E$10:$E$15)*D28) -> 935.12967
C29: samples+ (single order) | D29: 500 | E29: =(LOG(E17*10,2)/2+1+SUM(E10:E15))*Cur_rate/5 -> 0.62927817 | F29: =IF(ISNUMBER(E29),$D29*E29,"from costing") -> 314.63909
C30: samples | D30: 30 to 100 parts | E30: fixed price | F30: =400*(Cur_rate) -> 400
C32: Choice the MOQ to be offered ? | D32: 12000 | I32: NO | N32: Reminder :
D33: MINIMUN PRICE IS | E33: =IF(F33="from costing","Serial price",(F33/$D32)*1) -> Serial price | F33: =IF($D32>=F$18*$B$19,"from costing",F$29*2+LN($D32/$D$29)*(F$20-F$29*2)/LN(F$18/$D$29)+SUM($E$10:$E$15)*D32) -> from costing | N33: AVOCarbon do not want to have parts in stock not ordered.
E34: Cur /u | F34: T/O /MOQ | N34: That why we need to negotiate first the MOQ versus price with the customer
I35: find here | N35: Then Production will manage stock versus batch size versus number of set up
C36: PRICE Parameters / apps | D36: USED | I36: how balance
D37: 1.1 | I37: the price vs MOQ | K37: YES
D38: 5.8
K39: OK :-)
B40: Commercial strategy recommended :
B41: Use this minimum price and MOQ to improve current situaiton, arguing that AVOCarbon finance fixed strict rules because our cash is a critical topic.
B42: For new project, RFQ with low volume, we are only interesting if we can make a great margin (GMCD is not a good indicator in that case). Prices could be 2 times this minimum price.
...

Sheet Package offer
B2: Tool for calculation of package : | E2: complete/remplace the yellow cells
C4: qty/y | E4: Package offer
B5: Part #1 | C5: 3000 | D5: Kp | E5: =SUM(C5:C15) -> 7485 | F5: Kp | G5: Put the highest volume on part #1
B6: Part #2 | C6: 1000 | D6: Kp | E6: =E$5/C$5*C6 -> 2495 | F6: Kp
B7: Part #3 | C7: 1000 | D7: Kp | E7: =E$5/C$5*C7 -> 2495 | F7: Kp
B8: Part #4 | C8: 50 | D8: Kp | E8: =E$5/C$5*C8 -> 124.75 | F8: Kp
B9: Part #5 | C9: 500 | D9: Kp | E9: =E$5/C$5*C9 -> 1247.5 | F9: Kp
B10: Part #6 | C10: 500 | D10: Kp | E10: =E$5/C$5*C10 -> 1247.5 | F10: Kp
B11: Part #7 | C11: 300 | D11: Kp | E11: =E$5/C$5*C11 -> 748.5 | F11: Kp
B12: Part #8 | C12: 30 | D12: Kp | E12: =E$5/C$5*C12 -> 74.85 | F12: Kp
B13: Part #9 | C13: 5 | D13: Kp | E13: =E$5/C$5*C13 -> 12.475 | F13: Kp
B14: Part #10 | C14: 100 | D14: Kp | E14: =E$5/C$5*C14 -> 249.5 | F14: Kp
B15: Part #11 | C15: 1000 | D15: Kp | E15: =E$5/C$5*C15 -> 2495 | F15: Kp
B16: Part #12 | C16: 5 | D16: Kp | E16: =E$5/C$5*C16 -> 12.475 | F16: Kp
C17: remark : not applicable on a part consider as a small runner = qty/y < 1 batch
A19: Package offer can be consider only if volume of each part# are close (also close design and complecity - close price)
B20: Exemple 1: | C20: basic approach
D21: qty/y | G21: package offer
C22: Part A | D22: 2500 | E22: Kp | F22: OK | G22: 4500 | H22: Kp | I22: the full volume when volumes are close (max 25% difference on smallest)
C23: Part B | D23: 2000 | E23: Kp | F23: OK | G23: 4500 | H23: Kp | I23: the full volume when volumes are close (max 25% difference on smallest) | O23: =(2500-2000)/2000 -> 0.25
C24: Part C | D24: 10 | E24: Kp | F24: NOK | G24: Not applicable on small runner
B27: Example 2: | C27: (improved approach) large package from a subcontractor
D28: final customer | F28: qty/y
C29: Part A | D29: Customer A | F29: 3000 | G29: Kp | H29: 5050 | I29: Kp | J29: here it is the full qty of the package
C30: Part B | D30: Customer A | F30: 1000 | G30: Kp | H30: =H$29/F$29*F30 -> 1683.3333 | I30: Kp | J30: here it is ratio of the corresponding volume / full volume | O30: =(3000-1000)/1000 -> 2
C31: Part C | D31: Customer A | F31: 1000 | G31: Kp | H31: =H$29/F$29*F31 -> 1683.3333 | I31: Kp | J31: here it is ratio of the corresponding volume / full volume | O31: =(3000-1000)/1000 -> 2
C32: Part D | D32: Customer A | F32: 50 | G32: Kp | H32: =H$29/F$29*F32 -> 84.166667 | I32: Kp | J32: here it is ratio of the corresponding volume / full volume
C33: Part E | D33: Customer B | F33: 500 | G33: Kp | H33: 1000 | I33: Kp
C34: Part F | D34: Customer B | F34: 500 | G34: Kp | H34: 1000 | I34: Kp
C36: we need to split by customer
B38: Example 3: | C38: if more complex, with different applications, different brush sizes, different brush complexity and costs, different products..
C39: then Sales need to evalutate how we can calculate a package (with costing team and PLM)
B41: Exemple 4: | C41: case of a starter with 4 brushes = 2 with double layer on the top and 2 on the bottom
C42: (sames as exemple 1 = basic approach)
D43: qty/y | G43: package offer
C44: Part A | D44: 500 | E44: Kp | G44: 1000 | H44: Kp
C45: Part B | D45: 500 | E45: Kp | G45: 1000 | H45: Kp
B47: Example 5: | C47: case of a wiper with 3 brushes = 2 brushes with sames grade + 1 brush with a other grade
C48: (sames as exemple 1 = basic approach)
D49: qty/y | F49: package offer
...

Sheet Invest principle
A1: update : | B1: Feb 2025

Sheet Costing principle
B2: Previous appraoch | D2: New Approach
B3: (at plant level) | D3: (at group level) | E3: HOW is it EVALUATE ? | F3: What affects the cost ? | G3: How improve it ?
B4: RM | D4: RM (incl. Final Packaging) | E4: - Supplier costs | F4: Raw material cost & Indexation % of main drivers (Cu, silver) Dimension | G4: Change the design
B5: DIRECT | D5: DL | E5: - Direct labor (based on the best standards of the group in term of process) | F5: process routers manual or automatic process plant location | G5: Find a better alternative process
B6: COST | D6: VOH | E6: - standard cost/h for maintenance / plant - spare parts /process (%/year of a new machine value) - energy and tooling cost /process | F6: Energy and tooling cost | G6: Find a better alternative process
C7: Minimun PRICE | D7: tranportation & taxes | E7: - Inbound transportation for RM - Outbound transportation for intercompany flows and shipment to the customer | F7: Supplier location Customer incoterm Taxes | G7: Do it Local for local
B8: GROSS | D8: FOH + Admin | E8: It is a % of the DL + VOH /plant x volume effect = contribution to Fixed costs of the plants and Corporate costs (R&D / SALES / PURCHASES / COSTING / ACCOUNTING…) | F8: Turn Over (Volume effect) DL + VOH cost production plant locations | G8: Agressivity lever = Stategic decision of Olivier/Eric to reduce the contribution on FOH/Admin/Fees. It is arbitrary and disconnected from the cost calculation (rare case)
B9: MARGIN | D9: Fees
D10: Minimum EBITDA | E10: Based on a ROI target /product type and a financial calculation. (ROI = Return on Investment) Money we need to save for a good rentability | F10: Cost of all machines needed for production Serial order Payment conditions Stock and WIP level (incoterm, …) Investments & tooling payment conditions | G10: Frequency of Pick up, EXW incoterm Increase customer participation on Invest Change the ROI target (Olivier/Eric decision) and relaunch the calculation
B11: remark : previous calculated gross margin is NOT comparable to the numbers on the new costing file (it should higher)
B13: THEN THE SITUATION IS AS FOLLOWS :
C15: Case 1 | E15: Case 2
C16: market price < minimum AVO price | E16: market price > minimum AVO price
C17: We need to review our industrial process | E17: Sales job to get the best price
C18: or stategic decision (Agressivity, ROI) | F18: Maximum EBITDA
E19: possible price
E20: market price
B22: AVO min price
F23: Minimum EBITDA
B24: market price | F24: Fees
F25: FOH + Admin
F26: tranportation & taxes
F27: VOH
F28: DL
B29: 0 | F29: RM (incl. Final Packaging)
O64: =IF(G64<>0,H64/G64*(1-'RFQ Data'!$I$36),0) -> 0
O65: =IF(G65<>0,H65/G65*(1-'RFQ Data'!$I$36),0) -> 0
O66: =IF(G66<>0,H66/G66*(1-'RFQ Data'!$I$36),0) -> 0
O67: =IF(G67<>0,H67/G67*(1-'RFQ Data'!$I$36),0) -> 0
O68: =IF(G68<>0,H68/G68*(1-'RFQ Data'!$I$36),0) -> 0
O69: =IF(G69<>0,H69/G69*(1-'RFQ Data'!$I$36),0) -> 0
O70: =IF(G70<>0,H70/G70*(1-'RFQ Data'!$I$36),0) -> 0
O71: =IF(G71<>0,H71/G71*(1-'RFQ Data'!$I$36),0) -> 0
O72: =IF(G72<>0,H72/G72*(1-'RFQ Data'!$I$36),0) -> 0
O73: =IF(G73<>0,H73/G73*(1-'RFQ Data'!$I$36),0) -> 0
O74: =IF(G74<>0,H74/G74*(1-'RFQ Data'!$I$36),0) -> 0
O75: =IF(G75<>0,H75/G75*(1-'RFQ Data'!$I$36),0) -> 0
... O91: =IF(G91<>0,H91/G91*(1-'RFQ Data'!$I$36),0) -> 0

Sheet Samples guideline
A2: GUIDELINE for SAMPLES
B4: Prototype costs stay in the plant which has the benefice of the future production
B5: (customer projects).
B6: Customer order should arrive in this same plant.
B7: Needed internal invoicing must be organized.
B8: Pick-up must be organized to speed up the lead-time.
B10: Where produce the samples ? :
C11: Where it is faster and cheaper to get
C12: Local for local when tool is existing
C13: India is recommended for Starter and Industrial brushes (tamping..)
C14: Tianjin for small brushes
B16: Recommended Prices and Cession prices for Prototypes - BRUSH PL
C17: cust price | D17: Min price | E17: internal cession price
B18: qty (until) | C18: (ex : Europe) | D18: (ex : China) | E18: between AVO plants
B19: 100 | C19: 400 | D19: =C19/2 -> 200 | E19: 100
B20: 200 | C20: 600 | D20: =C20/2 -> 300 | E20: =C20/4 -> 150
B21: 500 | C21: 1000 | D21: =C21/2 -> 500 | E21: =C21/4 -> 250
B22: 2500 | C22: 2500 | D22: =C22/2 -> 1250 | E22: =C22/4 -> 625
C23: EUR | D23: EUR | E23: EUR
E24: + tooling cost
B26: Sales team negotiate with the customer.
B27: If samples failed on customer tests, next samples could be free of charge for the customer (Sales decision)
B28: Between AVOCarbon plants , find a fair deal in the team as the best profit for the group. The group prevails first.
